Traceback (most recent call last):
  File "/Volumes/m2.wd.black.sn850.1/dev/pyenv/versions/3.11/envs/python3.11/lib/python3.11/site-packages/jupyter_cache/executors/utils.py", line 51, in single_nb_execution
    executenb(
  File "/Volumes/m2.wd.black.sn850.1/dev/pyenv/versions/3.11/envs/python3.11/lib/python3.11/site-packages/nbclient/client.py", line 1204, in execute
    return NotebookClient(nb=nb, resources=resources, km=km, **kwargs).execute()
           ^^^^^^^^^^^^^^^^^^^^^^^^^^^^^^^^^^^^^^^^^^^^^^^^^^^^^^^^^^^^^^^^^^^^^
  File "/Volumes/m2.wd.black.sn850.1/dev/pyenv/versions/3.11/envs/python3.11/lib/python3.11/site-packages/nbclient/util.py", line 84, in wrapped
    return just_run(coro(*args, **kwargs))
           ^^^^^^^^^^^^^^^^^^^^^^^^^^^^^^^
  File "/Volumes/m2.wd.black.sn850.1/dev/pyenv/versions/3.11/envs/python3.11/lib/python3.11/site-packages/nbclient/util.py", line 62, in just_run
    return loop.run_until_complete(coro)
           ^^^^^^^^^^^^^^^^^^^^^^^^^^^^^
  File "/Volumes/m2.wd.black.sn850.1/dev/pyenv/versions/3.11.0/lib/python3.11/asyncio/base_events.py", line 650, in run_until_complete
    return future.result()
           ^^^^^^^^^^^^^^^
  File "/Volumes/m2.wd.black.sn850.1/dev/pyenv/versions/3.11.0/lib/python3.11/contextlib.py", line 222, in __aexit__
    await self.gen.athrow(typ, value, traceback)
  File "/Volumes/m2.wd.black.sn850.1/dev/pyenv/versions/3.11/envs/python3.11/lib/python3.11/site-packages/nbclient/client.py", line 608, in async_setup_kernel
    yield
  File "/Volumes/m2.wd.black.sn850.1/dev/pyenv/versions/3.11/envs/python3.11/lib/python3.11/site-packages/nbclient/client.py", line 663, in async_execute
    await self.async_execute_cell(
  File "/Volumes/m2.wd.black.sn850.1/dev/pyenv/versions/3.11/envs/python3.11/lib/python3.11/site-packages/nbclient/client.py", line 965, in async_execute_cell
    await self._check_raise_for_error(cell, cell_index, exec_reply)
  File "/Volumes/m2.wd.black.sn850.1/dev/pyenv/versions/3.11/envs/python3.11/lib/python3.11/site-packages/nbclient/client.py", line 862, in _check_raise_for_error
    raise CellExecutionError.from_cell_and_msg(cell, exec_reply_content)
nbclient.exceptions.CellExecutionError: An error occurred while executing the following cell:
------------------
import numpy as np
import matplotlib.pyplot as plt
import scipy
import sys  
sys.path.insert(0, '../../../src/python/lft')
sys.path.insert(1, '../../../src/python/signal')

from rcf import rcfis
import fold
from qiplot import plot_ts
import qisignal
from qisignal import signal
plt.style.use(['ggplot','../../presentation.mplstyle'])
------------------

[0;31m---------------------------------------------------------------------------[0m
[0;31mImportError[0m                               Traceback (most recent call last)
Cell [0;32mIn[1], line 12[0m
[1;32m     10[0m [38;5;28;01mfrom[39;00m [38;5;21;01mqiplot[39;00m [38;5;28;01mimport[39;00m plot_ts
[1;32m     11[0m [38;5;28;01mimport[39;00m [38;5;21;01mqisignal[39;00m
[0;32m---> 12[0m [38;5;28;01mfrom[39;00m [38;5;21;01mqisignal[39;00m [38;5;28;01mimport[39;00m signal
[1;32m     13[0m plt[38;5;241m.[39mstyle[38;5;241m.[39muse([[38;5;124m'[39m[38;5;124mggplot[39m[38;5;124m'[39m,[38;5;124m'[39m[38;5;124m../../presentation.mplstyle[39m[38;5;124m'[39m])

[0;31mImportError[0m: cannot import name 'signal' from 'qisignal' (/Volumes/m2.wd.black.sn850.1/dev/qi/super-qi/src/python/qisignal/qisignal.py)
ImportError: cannot import name 'signal' from 'qisignal' (/Volumes/m2.wd.black.sn850.1/dev/qi/super-qi/src/python/qisignal/qisignal.py)

